Workbook

Sheet 予算損益推移表
A1: 株式会社アカウントオフィス 予算損益推移表（2027年5月期／2028年5月期 10月まで）
A2: 単位：円（税抜） 新規採用：月給280,000円・2026年11月から（前提条件シートで変更可）
B4: 実績 | C4: 実績 | D4: 実績 | E4: 実績 | F4: 実績 | G4: 予算 | H4: 予算 | I4: 予算 | J4: 予算 | K4: 予算 | L4: 予算 | M4: 予算 | N4: 実績 | O4: 2027年5月期 | P4: 前期実績 | Q4: 前期比 | R4: 予算 | S4: 予算 | T4: 予算 | U4: 予算 | V4: 予算 | W4: 2028年5月期
A5: 勘定科目 | B5: 46174 | C5: 46204 | D5: 46235 | E5: 46266 | F5: 46296 | G5: 46327 | H5: 46357 | I5: 46388 | J5: 46419 | K5: 46447 | L5: 46478 | M5: 46508 | N5: 決算整理 | O5: 通期合計 | P5: 2026年5月期 | Q5: 増減 | R5: 46539 | S5: 46569 | T5: 46600 | U5: 46631 | V5: 46661 | W5: 6〜10月計
A6: 【売上高】
A7: コンサルティング収入 | B7: 2497442 | C7: 2697442 | D7: 3688351 | E7: 3088351 | F7: 3088351 | G7: =前提条件!$B$19 -> 3088351 | H7: =前提条件!$B$19 -> 3088351 | I7: =前提条件!$B$19 -> 3088351 | J7: =前提条件!$B$19 -> 3088351 | K7: =前提条件!$B$19 -> 3088351 | L7: =前提条件!$B$19 -> 3088351 | M7: =前提条件!$B$19 -> 3088351 | N7: 0 | O7: =SUM(B7:N7) -> 36678394 | P7: 24934849 | Q7: =O7-P7 -> 11743545 | R7: =前提条件!$B$19 -> 3088351 | S7: =前提条件!$B$19 -> 3088351 | T7: =前提条件!$B$19 -> 3088351 | U7: =前提条件!$B$19 -> 3088351 | V7: =前提条件!$B$19 -> 3088351 | W7: =SUM(R7:V7) -> 15441755
A8: 保険代理店収入 | B8: 0 | C8: 0 | D8: 0 | E8: 1131 | F8: 5400 | G8: =ROUND(AVERAGE($B8:$F8),0) -> 1306 | H8: =ROUND(AVERAGE($B8:$F8),0) -> 1306 | I8: =ROUND(AVERAGE($B8:$F8),0) -> 1306 | J8: =ROUND(AVERAGE($B8:$F8),0) -> 1306 | K8: =ROUND(AVERAGE($B8:$F8),0) -> 1306 | L8: =ROUND(AVERAGE($B8:$F8),0) -> 1306 | M8: =ROUND(AVERAGE($B8:$F8),0) -> 1306 | N8: 0 | O8: =SUM(B8:N8) -> 15673 | P8: 8622 | Q8: =O8-P8 -> 7051 | R8: =ROUND(AVERAGE($B8:$F8),0) -> 1306 | S8: =ROUND(AVERAGE($B8:$F8),0) -> 1306 | T8: =ROUND(AVERAGE($B8:$F8),0) -> 1306 | U8: =ROUND(AVERAGE($B8:$F8),0) -> 1306 | V8: =ROUND(AVERAGE($B8:$F8),0) -> 1306 | W8: =SUM(R8:V8) -> 6530
A9: 売上高合計 | B9: =SUM(B7,B8) -> 2497442 | C9: =SUM(C7,C8) -> 2697442 | D9: =SUM(D7,D8) -> 3688351 | E9: =SUM(E7,E8) -> 3089482 | F9: =SUM(F7,F8) -> 3093751 | G9: =SUM(G7,G8) -> 3089657 | H9: =SUM(H7,H8) -> 3089657 | I9: =SUM(I7,I8) -> 3089657 | ... N9: =SUM(N7,N8) -> 0 | O9: =SUM(B9:N9) -> 36694067 | P9: =SUM(P7,P8) -> 24943471 | Q9: =O9-P9 -> 11750596 | R9: =SUM(R7,R8) -> 3089657 | S9: =SUM(S7,S8) -> 3089657 | T9: =SUM(T7,T8) -> 3089657 | U9: =SUM(U7,U8) -> 3089657 | V9: =SUM(V7,V8) -> 3089657 | W9: =SUM(R9:V9) -> 15448285
A10: 売上原価 | B10: 0 | C10: 0 | D10: 0 | E10: 0 | F10: 0 | G10: 0 | H10: 0 | I10: 0 | J10: 0 | K10: 0 | L10: 0 | M10: 0 | N10: 0 | O10: =SUM(B10:N10) -> 0 | P10: 0 | Q10: =O10-P10 -> 0 | R10: 0 | S10: 0 | T10: 0 | U10: 0 | V10: 0 | W10: =SUM(R10:V10) -> 0
A11: 売上総利益 | B11: =B9-B10 -> 2497442 | C11: =C9-C10 -> 2697442 | D11: =D9-D10 -> 3688351 | E11: =E9-E10 -> 3089482 | F11: =F9-F10 -> 3093751 | G11: =G9-G10 -> 3089657 | H11: =H9-H10 -> 3089657 | I11: =I9-I10 -> 3089657 | ... N11: =N9-N10 -> 0 | O11: =SUM(B11:N11) -> 36694067 | P11: =P9-P10 -> 24943471 | Q11: =O11-P11 -> 11750596 | R11: =R9-R10 -> 3089657 | S11: =S9-S10 -> 3089657 | T11: =T9-T10 -> 3089657 | U11: =U9-U10 -> 3089657 | V11: =V9-V10 -> 3089657 | W11: =SUM(R11:V11) -> 15448285
A12: 【販売費及び一般管理費】
A13: 役員報酬 | B13: 1250000 | C13: 1250000 | D13: 1450000 | E13: 1450000 | F13: 1450000 | G13: =前提条件!$B$20 -> 1450000 | H13: =前提条件!$B$20 -> 1450000 | I13: =前提条件!$B$20 -> 1450000 | J13: =前提条件!$B$20 -> 1450000 | K13: =前提条件!$B$20 -> 1450000 | L13: =前提条件!$B$20 -> 1450000 | M13: =前提条件!$B$20 -> 1450000 | N13: 0 | O13: =SUM(B13:N13) -> 17000000 | P13: 9000000 | Q13: =O13-P13 -> 8000000 | R13: =前提条件!$B$20 -> 1450000 | S13: =前提条件!$B$20 -> 1450000 | T13: =前提条件!$B$20 -> 1450000 | U13: =前提条件!$B$20 -> 1450000 | V13: =前提条件!$B$20 -> 1450000 | W13: =SUM(R13:V13) -> 7250000
A14: 給料賃金 | B14: 335000 | C14: 335000 | D14: 335000 | E14: 335000 | F14: 335000 | G14: =前提条件!$B$21 -> 335000 | H14: =前提条件!$B$21 -> 335000 | I14: =前提条件!$B$21 -> 335000 | J14: =前提条件!$B$21 -> 335000 | K14: =前提条件!$B$21 -> 335000 | L14: =前提条件!$B$21 -> 335000 | M14: =前提条件!$B$21 -> 335000 | N14: 0 | O14: =SUM(B14:N14) -> 4020000 | P14: 4329659 | Q14: =O14-P14 -> -309659 | R14: =前提条件!$B$21 -> 335000 | S14: =前提条件!$B$21 -> 335000 | T14: =前提条件!$B$21 -> 335000 | U14: =前提条件!$B$21 -> 335000 | V14: =前提条件!$B$21 -> 335000 | W14: =SUM(R14:V14) -> 1675000
A15: 給料賃金（新規採用） | B15: 0 | C15: 0 | D15: 0 | E15: 0 | F15: 0 | G15: =IF(G$5>=前提条件!$B$5,前提条件!$B$6,0) -> 280000 | H15: =IF(H$5>=前提条件!$B$5,前提条件!$B$6,0) -> 280000 | I15: =IF(I$5>=前提条件!$B$5,前提条件!$B$6,0) -> 280000 | J15: =IF(J$5>=前提条件!$B$5,前提条件!$B$6,0) -> 280000 | K15: =IF(K$5>=前提条件!$B$5,前提条件!$B$6,0) -> 280000 | L15: =IF(L$5>=前提条件!$B$5,前提条件!$B$6,0) -> 280000 | M15: =IF(M$5>=前提条件!$B$5,前提条件!$B$6,0) -> 280000 | N15: 0 | O15: =SUM(B15:N15) -> 1960000 | P15: 0 | Q15: =O15-P15 -> 1960000 | R15: =IF(R$5>=前提条件!$B$5,前提条件!$B$6,0) -> 280000 | S15: =IF(S$5>=前提条件!$B$5,前提条件!$B$6,0) -> 280000 | T15: =IF(T$5>=前提条件!$B$5,前提条件!$B$6,0) -> 280000 | U15: =IF(U$5>=前提条件!$B$5,前提条件!$B$6,0) -> 280000 | V15: =IF(V$5>=前提条件!$B$5,前提条件!$B$6,0) -> 280000 | W15: =SUM(R15:V15) -> 1400000
A16: 賞与 | B16: 400000 | C16: 0 | D16: 0 | E16: 0 | F16: 0 | G16: =0+IF(AND(G15>0,OR(MONTH(G$5)=12,MONTH(G$5)=6)),前提条件!$B$7,0) -> 0 | H16: =500000+IF(AND(H15>0,OR(MONTH(H$5)=12,MONTH(H$5)=6)),前提条件!$B$7,0) -> 500000 | I16: =0+IF(AND(I15>0,OR(MONTH(I$5)=12,MONTH(I$5)=6)),前提条件!$B$7,0) -> 0 | J16: =0+IF(AND(J15>0,OR(MONTH(J$5)=12,MONTH(J$5)=6)),前提条件!$B$7,0) -> 0 | K16: =0+IF(AND(K15>0,OR(MONTH(K$5)=12,MONTH(K$5)=6)),前提条件!$B$7,0) -> 0 | L16: =0+IF(AND(L15>0,OR(MONTH(L$5)=12,MONTH(L$5)=6)),前提条件!$B$7,0) -> 0 | M16: =0+IF(AND(M15>0,OR(MONTH(M$5)=12,MONTH(M$5)=6)),前提条件!$B$7,0) -> 0 | N16: 0 | O16: =SUM(B16:N16) -> 900000 | P16: 900000 | Q16: =O16-P16 -> 0 | R16: =400000+IF(AND(R15>0,OR(MONTH(R$5)=12,MONTH(R$5)=6)),前提条件!$B$7,0) -> 400000 | S16: =0+IF(AND(S15>0,OR(MONTH(S$5)=12,MONTH(S$5)=6)),前提条件!$B$7,0) -> 0 | T16: =0+IF(AND(T15>0,OR(MONTH(T$5)=12,MONTH(T$5)=6)),前提条件!$B$7,0) -> 0 | U16: =0+IF(AND(U15>0,OR(MONTH(U$5)=12,MONTH(U$5)=6)),前提条件!$B$7,0) -> 0 | V16: =0+IF(AND(V15>0,OR(MONTH(V$5)=12,MONTH(V$5)=6)),前提条件!$B$7,0) -> 0 | W16: =SUM(R16:V16) -> 400000
A17: 法定福利費 | B17: 107235 | C17: 107235 | D17: 165995 | E17: 176167 | F17: 0 | G17: =前提条件!$B$22+ROUND(G16*前提条件!$B$16,0) -> 176167 | H17: =前提条件!$B$22+ROUND(H16*前提条件!$B$16,0) -> 255542 | I17: =前提条件!$B$22+ROUND(I16*前提条件!$B$16,0) -> 176167 | J17: =前提条件!$B$22+ROUND(J16*前提条件!$B$16,0) -> 176167 | K17: =前提条件!$B$22+ROUND(K16*前提条件!$B$16,0) -> 176167 | L17: =前提条件!$B$22+ROUND(L16*前提条件!$B$16,0) -> 176167 | M17: =前提条件!$B$22+ROUND(M16*前提条件!$B$16,0) -> 176167 | N17: 0 | O17: =SUM(B17:N17) -> 1869176 | P17: 1430750 | Q17: =O17-P17 -> 438426 | R17: =前提条件!$B$22+ROUND(R16*前提条件!$B$16,0) -> 239667 | S17: =前提条件!$B$22+ROUND(S16*前提条件!$B$16,0) -> 176167 | T17: =前提条件!$B$22+ROUND(T16*前提条件!$B$16,0) -> 176167 | U17: =前提条件!$B$22+ROUND(U16*前提条件!$B$16,0) -> 176167 | V17: =前提条件!$B$22+ROUND(V16*前提条件!$B$16,0) -> 176167 | W17: =SUM(R17:V17) -> 944335
A18: 法定福利費（新規採用） | B18: 0 | C18: 0 | D18: 0 | E18: 0 | F18: 0 | G18: =ROUND((G15+IF(AND(G15>0,OR(MONTH(G$5)=12,MONTH(G$5)=6)),前提条件!$B$7,0))*前提条件!$B$16,0) -> 44450 | H18: =ROUND((H15+IF(AND(H15>0,OR(MONTH(H$5)=12,MONTH(H$5)=6)),前提条件!$B$7,0))*前提条件!$B$16,0) -> 44450 | I18: =ROUND((I15+IF(AND(I15>0,OR(MONTH(I$5)=12,MONTH(I$5)=6)),前提条件!$B$7,0))*前提条件!$B$16,0) -> 44450 | J18: =ROUND((J15+IF(AND(J15>0,OR(MONTH(J$5)=12,MONTH(J$5)=6)),前提条件!$B$7,0))*前提条件!$B$16,0) -> 44450 | K18: =ROUND((K15+IF(AND(K15>0,OR(MONTH(K$5)=12,MONTH(K$5)=6)),前提条件!$B$7,0))*前提条件!$B$16,0) -> 44450 | L18: =ROUND((L15+IF(AND(L15>0,OR(MONTH(L$5)=12,MONTH(L$5)=6)),前提条件!$B$7,0))*前提条件!$B$16,0) -> 44450 | M18: =ROUND((M15+IF(AND(M15>0,OR(MONTH(M$5)=12,MONTH(M$5)=6)),前提条件!$B$7,0))*前提条件!$B$16,0) -> 44450 | N18: 0 | O18: =SUM(B18:N18) -> 311150 | P18: 0 | Q18: =O18-P18 -> 311150 | R18: =ROUND((R15+IF(AND(R15>0,OR(MONTH(R$5)=12,MONTH(R$5)=6)),前提条件!$B$7,0))*前提条件!$B$16,0) -> 44450 | S18: =ROUND((S15+IF(AND(S15>0,OR(MONTH(S$5)=12,MONTH(S$5)=6)),前提条件!$B$7,0))*前提条件!$B$16,0) -> 44450 | T18: =ROUND((T15+IF(AND(T15>0,OR(MONTH(T$5)=12,MONTH(T$5)=6)),前提条件!$B$7,0))*前提条件!$B$16,0) -> 44450 | U18: =ROUND((U15+IF(AND(U15>0,OR(MONTH(U$5)=12,MONTH(U$5)=6)),前提条件!$B$7,0))*前提条件!$B$16,0) -> 44450 | V18: =ROUND((V15+IF(AND(V15>0,OR(MONTH(V$5)=12,MONTH(V$5)=6)),前提条件!$B$7,0))*前提条件!$B$16,0) -> 44450 | W18: =SUM(R18:V18) -> 222250
A19: 業務委託料 | B19: 80940 | C19: 65660 | D19: 88340 | E19: 77560 | F19: 100060 | G19: =ROUND(AVERAGE($B19:$F19),0) -> 82512 | H19: =ROUND(AVERAGE($B19:$F19),0) -> 82512 | I19: =ROUND(AVERAGE($B19:$F19),0) -> 82512 | J19: =ROUND(AVERAGE($B19:$F19),0) -> 82512 | K19: =ROUND(AVERAGE($B19:$F19),0) -> 82512 | L19: =ROUND(AVERAGE($B19:$F19),0) -> 82512 | M19: =ROUND(AVERAGE($B19:$F19),0) -> 82512 | N19: 0 | O19: =SUM(B19:N19) -> 990144 | P19: 974688 | Q19: =O19-P19 -> 15456 | R19: =ROUND(AVERAGE($B19:$F19),0) -> 82512 | S19: =ROUND(AVERAGE($B19:$F19),0) -> 82512 | T19: =ROUND(AVERAGE($B19:$F19),0) -> 82512 | U19: =ROUND(AVERAGE($B19:$F19),0) -> 82512 | V19: =ROUND(AVERAGE($B19:$F19),0) -> 82512 | W19: =SUM(R19:V19) -> 412560
A20: 広告宣伝費 | B20: 0 | C20: 0 | D20: 0 | E20: 0 | F20: 0 | G20: 0 | H20: 0 | I20: 0 | J20: 0 | K20: 0 | L20: 0 | M20: 0 | N20: 0 | O20: =SUM(B20:N20) -> 0 | P20: 50000 | Q20: =O20-P20 -> -50000 | R20: 0 | S20: 0 | T20: 0 | U20: 0 | V20: 0 | W20: =SUM(R20:V20) -> 0
A21: 接待交際費 | B21: 185208 | C21: 90938 | D21: 144173 | E21: 264670 | F21: 56743 | G21: =ROUND(AVERAGE($B21:$F21),0) -> 148346 | H21: =ROUND(AVERAGE($B21:$F21),0) -> 148346 | I21: =ROUND(AVERAGE($B21:$F21),0) -> 148346 | J21: =ROUND(AVERAGE($B21:$F21),0) -> 148346 | K21: =ROUND(AVERAGE($B21:$F21),0) -> 148346 | L21: =ROUND(AVERAGE($B21:$F21),0) -> 148346 | M21: =ROUND(AVERAGE($B21:$F21),0) -> 148346 | N21: 0 | O21: =SUM(B21:N21) -> 1780154 | P21: 1529626 | Q21: =O21-P21 -> 250528 | R21: =ROUND(AVERAGE($B21:$F21),0) -> 148346 | S21: =ROUND(AVERAGE($B21:$F21),0) -> 148346 | T21: =ROUND(AVERAGE($B21:$F21),0) -> 148346 | U21: =ROUND(AVERAGE($B21:$F21),0) -> 148346 | V21: =ROUND(AVERAGE($B21:$F21),0) -> 148346 | W21: =SUM(R21:V21) -> 741730
A22: 旅費交通費 | B22: 31600 | C22: 4040 | D22: 71662 | E22: 49645 | F22: 7639 | G22: =ROUND(AVERAGE($B22:$F22),0) -> 32917 | H22: =ROUND(AVERAGE($B22:$F22),0) -> 32917 | I22: =ROUND(AVERAGE($B22:$F22),0) -> 32917 | J22: =ROUND(AVERAGE($B22:$F22),0) -> 32917 | K22: =ROUND(AVERAGE($B22:$F22),0) -> 32917 | L22: =ROUND(AVERAGE($B22:$F22),0) -> 32917 | M22: =ROUND(AVERAGE($B22:$F22),0) -> 32917 | N22: 0 | O22: =SUM(B22:N22) -> 395005 | P22: 522774 | Q22: =O22-P22 -> -127769 | R22: =ROUND(AVERAGE($B22:$F22),0) -> 32917 | S22: =ROUND(AVERAGE($B22:$F22),0) -> 32917 | T22: =ROUND(AVERAGE($B22:$F22),0) -> 32917 | U22: =ROUND(AVERAGE($B22:$F22),0) -> 32917 | V22: =ROUND(AVERAGE($B22:$F22),0) -> 32917 | W22: =SUM(R22:V22) -> 164585
A23: 通信費 | B23: 30349 | C23: 47171 | D23: 61103 | E23: 48499 | F23: 43764 | G23: =ROUND(AVERAGE($B23:$F23),0) -> 46177 | H23: =ROUND(AVERAGE($B23:$F23),0) -> 46177 | I23: =ROUND(AVERAGE($B23:$F23),0) -> 46177 | J23: =ROUND(AVERAGE($B23:$F23),0) -> 46177 | K23: =ROUND(AVERAGE($B23:$F23),0) -> 46177 | L23: =ROUND(AVERAGE($B23:$F23),0) -> 46177 | M23: =ROUND(AVERAGE($B23:$F23),0) -> 46177 | N23: 0 | O23: =SUM(B23:N23) -> 554125 | P23: 450930 | Q23: =O23-P23 -> 103195 | R23: =ROUND(AVERAGE($B23:$F23),0) -> 46177 | S23: =ROUND(AVERAGE($B23:$F23),0) -> 46177 | T23: =ROUND(AVERAGE($B23:$F23),0) -> 46177 | U23: =ROUND(AVERAGE($B23:$F23),0) -> 46177 | V23: =ROUND(AVERAGE($B23:$F23),0) -> 46177 | W23: =SUM(R23:V23) -> 230885
A24: 修繕費 | B24: 0 | C24: 37364 | D24: 0 | E24: 0 | F24: 0 | G24: =ROUND(AVERAGE($B24:$F24),0) -> 7473 | H24: =ROUND(AVERAGE($B24:$F24),0) -> 7473 | I24: =ROUND(AVERAGE($B24:$F24),0) -> 7473 | J24: =ROUND(AVERAGE($B24:$F24),0) -> 7473 | K24: =ROUND(AVERAGE($B24:$F24),0) -> 7473 | L24: =ROUND(AVERAGE($B24:$F24),0) -> 7473 | M24: =ROUND(AVERAGE($B24:$F24),0) -> 7473 | N24: 0 | O24: =SUM(B24:N24) -> 89675 | P24: 102909 | Q24: =O24-P24 -> -13234 | R24: =ROUND(AVERAGE($B24:$F24),0) -> 7473 | S24: =ROUND(AVERAGE($B24:$F24),0) -> 7473 | T24: =ROUND(AVERAGE($B24:$F24),0) -> 7473 | U24: =ROUND(AVERAGE($B24:$F24),0) -> 7473 | V24: =ROUND(AVERAGE($B24:$F24),0) -> 7473 | W24: =SUM(R24:V24) -> 37365
A25: 備品・消耗品費 | B25: 18952 | C25: 35062 | D25: 85771 | E25: 15372 | F25: 79643 | G25: =ROUND(AVERAGE($B25:$F25),0) -> 46960 | H25: =ROUND(AVERAGE($B25:$F25),0) -> 46960 | I25: =ROUND(AVERAGE($B25:$F25),0) -> 46960 | J25: =ROUND(AVERAGE($B25:$F25),0) -> 46960 | K25: =ROUND(AVERAGE($B25:$F25),0) -> 46960 | L25: =ROUND(AVERAGE($B25:$F25),0) -> 46960 | M25: =ROUND(AVERAGE($B25:$F25),0) -> 46960 | N25: 0 | O25: =SUM(B25:N25) -> 563520 | P25: 284892 | Q25: =O25-P25 -> 278628 | R25: =ROUND(AVERAGE($B25:$F25),0) -> 46960 | S25: =ROUND(AVERAGE($B25:$F25),0) -> 46960 | T25: =ROUND(AVERAGE($B25:$F25),0) -> 46960 | U25: =ROUND(AVERAGE($B25:$F25),0) -> 46960 | V25: =ROUND(AVERAGE($B25:$F25),0) -> 46960 | W25: =SUM(R25:V25) -> 234800
A26: 車両費 | B26: 0 | C26: 16223 | D26: 13227 | E26: 11834 | F26: 5675 | G26: =ROUND(AVERAGE($B26:$F26),0) -> 9392 | H26: =ROUND(AVERAGE($B26:$F26),0) -> 9392 | I26: =ROUND(AVERAGE($B26:$F26),0) -> 9392 | J26: =ROUND(AVERAGE($B26:$F26),0) -> 9392 | K26: =ROUND(AVERAGE($B26:$F26),0) -> 9392 | L26: =ROUND(AVERAGE($B26:$F26),0) -> 9392 | M26: =ROUND(AVERAGE($B26:$F26),0) -> 9392 | N26: 0 | O26: =SUM(B26:N26) -> 112703 | P26: 114895 | Q26: =O26-P26 -> -2192 | R26: =ROUND(AVERAGE($B26:$F26),0) -> 9392 | S26: =ROUND(AVERAGE($B26:$F26),0) -> 9392 | T26: =ROUND(AVERAGE($B26:$F26),0) -> 9392 | U26: =ROUND(AVERAGE($B26:$F26),0) -> 9392 | V26: =ROUND(AVERAGE($B26:$F26),0) -> 9392 | W26: =SUM(R26:V26) -> 46960
A27: リース料 | B27: 12000 | C27: 12000 | D27: 12000 | E27: 12000 | F27: 12000 | G27: =前提条件!$B$24 -> 12000 | H27: =前提条件!$B$24 -> 12000 | I27: =前提条件!$B$24 -> 12000 | J27: =前提条件!$B$24 -> 12000 | K27: =前提条件!$B$24 -> 12000 | L27: =前提条件!$B$24 -> 12000 | M27: =前提条件!$B$24 -> 12000 | N27: 0 | O27: =SUM(B27:N27) -> 144000 | P27: 144000 | Q27: =O27-P27 -> 0 | R27: =前提条件!$B$24 -> 12000 | S27: =前提条件!$B$24 -> 12000 | T27: =前提条件!$B$24 -> 12000 | U27: =前提条件!$B$24 -> 12000 | V27: =前提条件!$B$24 -> 12000 | W27: =SUM(R27:V27) -> 60000
A28: 地代家賃 | B28: 198150 | C28: 198150 | D28: 198150 | E28: 198150 | F28: 334350 | G28: =前提条件!$B$23 -> 334350 | H28: =前提条件!$B$23 -> 334350 | I28: =前提条件!$B$23 -> 334350 | J28: =前提条件!$B$23 -> 334350 | K28: =前提条件!$B$23 -> 334350 | L28: =前提条件!$B$23 -> 334350 | M28: =前提条件!$B$23 -> 334350 | N28: 0 | O28: =SUM(B28:N28) -> 3467400 | P28: 241562 | Q28: =O28-P28 -> 3225838 | R28: =前提条件!$B$23 -> 334350 | S28: =前提条件!$B$23 -> 334350 | T28: =前提条件!$B$23 -> 334350 | U28: =前提条件!$B$23 -> 334350 | V28: =前提条件!$B$23 -> 334350 | W28: =SUM(R28:V28) -> 1671750
A29: 保険料 | B29: 800 | C29: 70750 | D29: 11190 | E29: 0 | F29: 0 | G29: 0 | H29: 171900 | I29: 0 | J29: 0 | K29: 0 | L29: 0 | M29: 0 | N29: 0 | O29: =SUM(B29:N29) -> 254640 | P29: 183090 | Q29: =O29-P29 -> 71550 | R29: 800 | S29: 70750 | T29: 11190 | U29: 0 | V29: 0 | W29: =SUM(R29:V29) -> 82740
A30: 租税公課 | B30: 500 | C30: 1040 | D30: 0 | E30: 0 | F30: 0 | G30: 0 | H30: 26900 | I30: 0 | J30: 0 | K30: 0 | L30: 0 | M30: 36000 | N30: 0 | O30: =SUM(B30:N30) -> 64440 | P30: 64940 | Q30: =O30-P30 -> -500 | R30: 500 | S30: 1040 | T30: 0 | U30: 0 | V30: 0 | W30: =SUM(R30:V30) -> 1540
A31: 支払手数料 | B31: 11003 | C31: 22425 | D31: 11083 | E31: 11223 | F31: 26266 | G31: =ROUND(AVERAGE($B31:$F31),0) -> 16400 | H31: =ROUND(AVERAGE($B31:$F31),0) -> 16400 | I31: =ROUND(AVERAGE($B31:$F31),0) -> 16400 | J31: =ROUND(AVERAGE($B31:$F31),0) -> 16400 | K31: =ROUND(AVERAGE($B31:$F31),0) -> 16400 | L31: =ROUND(AVERAGE($B31:$F31),0) -> 16400 | M31: =ROUND(AVERAGE($B31:$F31),0) -> 16400 | N31: 0 | O31: =SUM(B31:N31) -> 196800 | P31: 252555 | Q31: =O31-P31 -> -55755 | R31: =ROUND(AVERAGE($B31:$F31),0) -> 16400 | S31: =ROUND(AVERAGE($B31:$F31),0) -> 16400 | T31: =ROUND(AVERAGE($B31:$F31),0) -> 16400 | U31: =ROUND(AVERAGE($B31:$F31),0) -> 16400 | V31: =ROUND(AVERAGE($B31:$F31),0) -> 16400 | W31: =SUM(R31:V31) -> 82000
A32: 会議費 | B32: 29846 | C32: 26741 | D32: 22519 | E32: 142279 | F32: 2541 | G32: =ROUND(AVERAGE($B32:$F32),0) -> 44785 | H32: =ROUND(AVERAGE($B32:$F32),0) -> 44785 | I32: =ROUND(AVERAGE($B32:$F32),0) -> 44785 | J32: =ROUND(AVERAGE($B32:$F32),0) -> 44785 | K32: =ROUND(AVERAGE($B32:$F32),0) -> 44785 | L32: =ROUND(AVERAGE($B32:$F32),0) -> 44785 | M32: =ROUND(AVERAGE($B32:$F32),0) -> 44785 | N32: 0 | O32: =SUM(B32:N32) -> 537421 | P32: 276401 | Q32: =O32-P32 -> 261020 | R32: =ROUND(AVERAGE($B32:$F32),0) -> 44785 | S32: =ROUND(AVERAGE($B32:$F32),0) -> 44785 | T32: =ROUND(AVERAGE($B32:$F32),0) -> 44785 | U32: =ROUND(AVERAGE($B32:$F32),0) -> 44785 | V32: =ROUND(AVERAGE($B32:$F32),0) -> 44785 | W32: =SUM(R32:V32) -> 223925
A33: 新聞図書費 | B33: 20982 | C33: 12782 | D33: 12782 | E33: 12782 | F33: 12810 | G33: =ROUND(AVERAGE($B33:$F33),0) -> 14428 | H33: =ROUND(AVERAGE($B33:$F33),0) -> 14428 | I33: =ROUND(AVERAGE($B33:$F33),0) -> 14428 | J33: =ROUND(AVERAGE($B33:$F33),0) -> 14428 | K33: =ROUND(AVERAGE($B33:$F33),0) -> 14428 | L33: =ROUND(AVERAGE($B33:$F33),0) -> 14428 | M33: =ROUND(AVERAGE($B33:$F33),0) -> 14428 | N33: 0 | O33: =SUM(B33:N33) -> 173134 | P33: 142311 | Q33: =O33-P33 -> 30823 | R33: =ROUND(AVERAGE($B33:$F33),0) -> 14428 | S33: =ROUND(AVERAGE($B33:$F33),0) -> 14428 | T33: =ROUND(AVERAGE($B33:$F33),0) -> 14428 | U33: =ROUND(AVERAGE($B33:$F33),0) -> 14428 | V33: =ROUND(AVERAGE($B33:$F33),0) -> 14428 | W33: =SUM(R33:V33) -> 72140
A34: 減価償却費 | B34: 0 | C34: 0 | D34: 0 | E34: 0 | F34: 0 | G34: 0 | H34: 0 | I34: 0 | J34: 0 | K34: 0 | L34: 0 | M34: 0 | N34: 1259910 | O34: =SUM(B34:N34) -> 1259910 | P34: 1068367 | Q34: =O34-P34 -> 191543 | R34: =ROUND(前提条件!$B$30/12,0) -> 104993 | S34: =ROUND(前提条件!$B$30/12,0) -> 104993 | T34: =ROUND(前提条件!$B$30/12,0) -> 104993 | U34: =ROUND(前提条件!$B$30/12,0) -> 104993 | V34: =ROUND(前提条件!$B$30/12,0) -> 104993 | W34: =SUM(R34:V34) -> 524965
A35: 雑費 | B35: 12604 | C35: 4966 | D35: 63609 | E35: 5422 | F35: 4182 | G35: =ROUND(AVERAGE($B35:$F35),0) -> 18157 | H35: =ROUND(AVERAGE($B35:$F35),0) -> 18157 | I35: =ROUND(AVERAGE($B35:$F35),0) -> 18157 | J35: =ROUND(AVERAGE($B35:$F35),0) -> 18157 | K35: =ROUND(AVERAGE($B35:$F35),0) -> 18157 | L35: =ROUND(AVERAGE($B35:$F35),0) -> 18157 | M35: =ROUND(AVERAGE($B35:$F35),0) -> 18157 | N35: 0 | O35: =SUM(B35:N35) -> 217882 | P35: 107180 | Q35: =O35-P35 -> 110702 | R35: =ROUND(AVERAGE($B35:$F35),0) -> 18157 | S35: =ROUND(AVERAGE($B35:$F35),0) -> 18157 | T35: =ROUND(AVERAGE($B35:$F35),0) -> 18157 | U35: =ROUND(AVERAGE($B35:$F35),0) -> 18157 | V35: =ROUND(AVERAGE($B35:$F35),0) -> 18157 | W35: =SUM(R35:V35) -> 90785
A36: 販売費及び一般管理費合計 | B36: =SUM(B13,B14,B15,B16,B17,B18,B19,B20,B21,B22,B23,B24,B25,B26,B27,B28,B29,B30,B31,B32,B33,B34,B35) -> 2725169 | C36: =SUM(C13,C14,C15,C16,C17,C18,C19,C20,C21,C22,C23,C24,C25,C26,C27,C28,C29,C30,C31,C32,C33,C34,C35) -> 2337547 | D36: =SUM(D13,D14,D15,D16,D17,D18,D19,D20,D21,D22,D23,D24,D25,D26,D27,D28,D29,D30,D31,D32,D33,D34,D35) -> 2746604 | E36: =SUM(E13,E14,E15,E16,E17,E18,E19,E20,E21,E22,E23,E24,E25,E26,E27,E28,E29,E30,E31,E32,E33,E34,E35) -> 2810603 | F36: =SUM(F13,F14,F15,F16,F17,F18,F19,F20,F21,F22,F23,F24,F25,F26,F27,F28,F29,F30,F31,F32,F33,F34,F35) -> 2470673 | G36: =SUM(G13,G14,G15,G16,G17,G18,G19,G20,G21,G22,G23,G24,G25,G26,G27,G28,G29,G30,G31,G32,G33,G34,G35) -> 3099514 | H36: =SUM(H13,H14,H15,H16,H17,H18,H19,H20,H21,H22,H23,H24,H25,H26,H27,H28,H29,H30,H31,H32,H33,H34,H35) -> 3877689 | I36: =SUM(I13,I14,I15,I16,I17,I18,I19,I20,I21,I22,I23,I24,I25,I26,I27,I28,I29,I30,I31,I32,I33,I34,I35) -> 3099514 | ... N36: =SUM(N13,N14,N15,N16,N17,N18,N19,N20,N21,N22,N23,N24,N25,N26,N27,N28,N29,N30,N31,N32,N33,N34,N35) -> 1259910 | O36: =SUM(B36:N36) -> 36861279 | P36: =SUM(P13,P14,P15,P16,P17,P18,P19,P20,P21,P22,P23,P24,P25,P26,P27,P28,P29,P30,P31,P32,P33,P34,P35) -> 22171529 | Q36: =O36-P36 -> 14689750 | R36: =SUM(R13,R14,R15,R16,R17,R18,R19,R20,R21,R22,R23,R24,R25,R26,R27,R28,R29,R30,R31,R32,R33,R34,R35) -> 3669307 | S36: =SUM(S13,S14,S15,S16,S17,S18,S19,S20,S21,S22,S23,S24,S25,S26,S27,S28,S29,S30,S31,S32,S33,S34,S35) -> 3276297 | T36: =SUM(T13,T14,T15,T16,T17,T18,T19,T20,T21,T22,T23,T24,T25,T26,T27,T28,T29,T30,T31,T32,T33,T34,T35) -> 3215697 | U36: =SUM(U13,U14,U15,U16,U17,U18,U19,U20,U21,U22,U23,U24,U25,U26,U27,U28,U29,U30,U31,U32,U33,U34,U35) -> 3204507 | V36: =SUM(V13,V14,V15,V16,V17,V18,V19,V20,V21,V22,V23,V24,V25,V26,V27,V28,V29,V30,V31,V32,V33,V34,V35) -> 3204507 | W36: =SUM(R36:V36) -> 16570315
A37: 営業利益 | B37: =B11-B36 -> -227727 | C37: =C11-C36 -> 359895 | D37: =D11-D36 -> 941747 | E37: =E11-E36 -> 278879 | F37: =F11-F36 -> 623078 | G37: =G11-G36 -> -9857 | H37: =H11-H36 -> -788032 | I37: =I11-I36 -> -9857 | ... N37: =N11-N36 -> -1259910 | O37: =SUM(B37:N37) -> -167212 | P37: =P11-P36 -> 2771942 | Q37: =O37-P37 -> -2939154 | R37: =R11-R36 -> -579650 | S37: =S11-S36 -> -186640 | T37: =T11-T36 -> -126040 | U37: =U11-U36 -> -114850 | V37: =V11-V36 -> -114850 | W37: =SUM(R37:V37) -> -1122030
A38: 【営業外損益】
A39: 受取利息 | B39: 2416 | C39: 1891 | D39: 2309 | E39: 2984 | F39: 1899 | G39: =ROUND(AVERAGE($B39:$F39),0) -> 2300 | H39: =ROUND(AVERAGE($B39:$F39),0) -> 2300 | I39: =ROUND(AVERAGE($B39:$F39),0) -> 2300 | J39: =ROUND(AVERAGE($B39:$F39),0) -> 2300 | K39: =ROUND(AVERAGE($B39:$F39),0) -> 2300 | L39: =ROUND(AVERAGE($B39:$F39),0) -> 2300 | M39: =ROUND(AVERAGE($B39:$F39),0) -> 2300 | N39: 0 | O39: =SUM(B39:N39) -> 27599 | P39: 16707 | Q39: =O39-P39 -> 10892 | R39: =ROUND(AVERAGE($B39:$F39),0) -> 2300 | S39: =ROUND(AVERAGE($B39:$F39),0) -> 2300 | T39: =ROUND(AVERAGE($B39:$F39),0) -> 2300 | U39: =ROUND(AVERAGE($B39:$F39),0) -> 2300 | V39: =ROUND(AVERAGE($B39:$F39),0) -> 2300 | W39: =SUM(R39:V39) -> 11500
A40: 受取配当金 | B40: 1497 | C40: 0 | D40: 0 | E40: 0 | F40: 0 | G40: 0 | H40: 0 | I40: 0 | J40: 0 | K40: 0 | L40: 0 | M40: 0 | N40: 0 | O40: =SUM(B40:N40) -> 1497 | P40: 1000 | Q40: =O40-P40 -> 497 | R40: 1497 | S40: 0 | T40: 0 | U40: 0 | V40: 0 | W40: =SUM(R40:V40) -> 1497
A41: 雑収入 | B41: 0 | C41: 0 | D41: 499254 | E41: 0 | F41: 0 | G41: 0 | H41: 0 | I41: 0 | J41: 0 | K41: 0 | L41: 0 | M41: 0 | N41: 0 | O41: =SUM(B41:N41) -> 499254 | P41: 734195 | Q41: =O41-P41 -> -234941 | R41: 0 | S41: 0 | T41: 0 | U41: 0 | V41: 0 | W41: =SUM(R41:V41) -> 0
...

Sheet 前提条件
A1: 前提条件（黄色セル＝変更可能な入力値）
A4: ■ 新規採用
A5: 採用開始月 | B5: 46327 | C5: ユーザー指定（2026年11月）。月の1日で入力
A6: 新規採用者 月給 | B6: 280000 | C6: ユーザー指定
A7: 新規採用者 賞与（1回あたり） | B7: 0 | C7: 未定のため0円。支給する場合は入力（12月・6月に計上）
A9: ■ 会社負担の社会保険料率（概算・要確認）
A10: 健康保険（事業主負担） | B10: 0.051 | C10: 協会けんぽ大阪の概算（全体約10.2%の折半）。40歳以上は介護保険分が加算
A11: 厚生年金（事業主負担） | B11: 0.0915 | C11: 18.3%の折半
A12: 子ども・子育て支援金（事業主負担） | B12: 0.00115 | C12: 2026年4月分から。概算
A13: 子ども・子育て拠出金 | B13: 0.0036 | C13: 事業主全額負担
A14: 雇用保険（事業主負担） | B14: 0.0085 | C14: 一般の事業の概算。年度の料率を要確認
A15: 労災保険 | B15: 0.003 | C15: その他の各種事業の概算
A16: 合計（新規採用者の法定福利費率） | B16: =SUM(B10:B15) -> 0.15875 | C16: 月給×この率を「法定福利費（新規採用）」に計上。標準報酬月額＝月給と仮定
A18: ■ 既存の固定費（予算月額）
A19: コンサルティング収入 | B19: 3088351 | C19: 2026年10月実績。うち76万円はリベ大税理士法人経由の役員報酬60万円・家賃16万円と相殺される通り抜け
A20: 役員報酬 | B20: 1450000 | C20: 2026年10月実績（会社支払85万円＋リベ大経由60万円）
A21: 給料賃金（既存） | B21: 335000 | C21: 2026年10月実績
A22: 法定福利費（既存） | B22: 176167 | C22: 2026年9月実績（10月は未計上のため9月を採用）。役員報酬の増額に伴う随時改定で増える可能性あり
A23: 地代家賃 | B23: 334350 | C23: 2026年10月実績（UR社宅196,200＋駐車場38,150＋リベ大経由160,000－社宅家賃徴収60,000）
A24: リース料 | B24: 12000 | C24: 毎月定額
A25: 支払利息 | B25: 7361 | C25: 2026年10月実績（返済に伴い実際は少しずつ減少）
A27: ■ 決算・税金
A28: 法人税等の実効負担率 | B28: 0.2044 | C28: 前期（2026年5月期）実績：法人税等701,453÷税引前利益3,432,063
A29: 法人住民税均等割（最低額） | B29: 70000 | C29: 赤字でも発生する最低額
A30: 2028年5月期 減価償却費見込（年額） | B30: 1259910 | C30: 当期と同額と仮定し、月割で計上
A32: ■ 凡例
A33: 青字：手入力の値（予算の前提） 黒字：計算式 緑字：前提条件シートへのリンク
A34: 灰色の列：マネーフォワード クラウド会計の実績（2026年11月1日時点）
A35: その他の経費の予算月額は、2026年6〜10月実績の平均（予算表の各行の式で自動計算）
A36: 保険料・租税公課・賞与・受取配当金は、前期・当期の実績月に合わせて季節計上
A37: 2026年10月の実績データは未計上の科目あり（法定福利費 0円）。月次確定後に要更新
